Workbook

Sheet Daily targets 2027
A1: Parakeet Café · 2027 daily sales: the monthly manager targets
A2: Each month of the monthly manager targets (Parakeet_2027_Manager_Targets.xlsx) split over its days by the daily model: Prophet (with every special day) and a tree model trained on all stores, blended, retrained on data through Oct 14, 2026. Every month adds up exactly to the monthly figure (see 'Check'). Blue = values from the analysis; black = formulas.
A4: Date | B4: Day | C4: Month | D4: Beverly Hills | E4: Brentwood | F4: Carlsbad | G4: Coronado | H4: Del Mar Café | I4: La Jolla Café | J4: La Jolla Juicery | K4: Little Italy Café | L4: Newport Beach | M4: La Jolla Cove | N4: Total
A5: 46388 | B5: Fri | C5: Jan 2027 | D5: 7942.18 | E5: 7934.36 | F5: 11867.78 | G5: 14720.38 | H5: 14608.72 | I5: 9494.2 | J5: 2381.93 | K5: 13607.65 | L5: 15572.95 | M5: 2110.56 | N5: =SUM(D5:M5) -> 100240.71
A6: 46389 | B6: Sat | C6: Jan 2027 | D6: 7825.61 | E6: 8890 | F6: 12742.54 | G6: 16199.92 | H6: 15575.69 | I6: 10001.23 | J6: 2948.62 | K6: 12999.23 | L6: 14295.1 | M6: 2367.28 | N6: =SUM(D6:M6) -> 103845.22
A7: 46390 | B7: Sun | C7: Jan 2027 | D7: 7503.44 | E7: 8152.68 | F7: 11360 | G7: 14712.48 | H7: 14214.18 | I7: 8681.7 | J7: 2364.64 | K7: 10896.52 | L7: 13950.42 | M7: 2216.99 | N7: =SUM(D7:M7) -> 94053.05
A8: 46391 | B8: Mon | C8: Jan 2027 | D8: 7191.36 | E8: 5981.43 | F8: 8788.2 | G8: 9345.59 | H8: 10615.24 | I8: 7515.57 | J8: 2066.63 | K8: 7538.82 | L8: 7106.69 | M8: 1174.59 | N8: =SUM(D8:M8) -> 67324.12
A9: 46392 | B9: Tue | C9: Jan 2027 | D9: 7467.29 | E9: 6202.9 | F9: 8842.01 | G9: 8302.48 | H9: 10964.67 | I9: 7461.93 | J9: 2072.22 | K9: 6316.31 | L9: 6790.59 | M9: 997.81 | N9: =SUM(D9:M9) -> 65418.21
A10: 46393 | B10: Wed | C10: Jan 2027 | D10: 7494.55 | E10: 6539.67 | F10: 9186.01 | G10: 8061.57 | H10: 11449.93 | I10: 7447.14 | J10: 2089.66 | K10: 6349.45 | L10: 7080.56 | M10: 974.19 | N10: =SUM(D10:M10) -> 66672.73
A11: 46394 | B11: Thu | C11: Jan 2027 | D11: 7448.33 | E11: 6859.71 | F11: 9671.08 | G11: 8237.81 | H11: 12014.83 | I11: 7874.63 | J11: 2222.79 | K11: 6766.38 | L11: 7477.06 | M11: 1083.51 | N11: =SUM(D11:M11) -> 69656.13
A12: 46395 | B12: Fri | C12: Jan 2027 | D12: 7474.64 | E12: 7547.96 | F12: 10949.33 | G12: 9900.19 | H12: 13142.46 | I12: 8532.74 | J12: 2422.47 | K12: 8650.07 | L12: 9136.01 | M12: 1438.66 | N12: =SUM(D12:M12) -> 79194.53
A13: 46396 | B13: Sat | C13: Jan 2027 | D13: 7783.08 | E13: 9714.44 | F13: 12769.69 | G13: 12757.14 | H13: 15548.59 | I13: 9839.13 | J13: 2917.08 | K13: 11168.55 | L13: 14274.09 | M13: 2015.03 | N13: =SUM(D13:M13) -> 98786.82
A14: 46397 | B14: Sun | C14: Jan 2027 | D14: 7676.1 | E14: 9445.76 | F14: 12193.28 | G14: 12404.47 | H14: 15127.5 | I14: 9204.7 | J14: 2496.07 | K14: 10807.13 | L14: 14809.19 | M14: 2025.69 | N14: =SUM(D14:M14) -> 96189.89
A15: 46398 | B15: Mon | C15: Jan 2027 | D15: 7143.92 | E15: 6570.51 | F15: 8724.59 | G15: 7231.84 | H15: 10854.02 | I15: 7550.94 | J15: 2009.08 | K15: 6798.65 | L15: 7493.42 | M15: 1061.11 | N15: =SUM(D15:M15) -> 65438.08
A16: 46399 | B16: Tue | C16: Jan 2027 | D16: 7435.31 | E16: 6757.14 | F16: 8803.56 | G16: 6647.05 | H16: 11344.8 | I16: 7538.96 | J16: 2007.68 | K16: 6065.71 | L16: 7283.47 | M16: 904.48 | N16: =SUM(D16:M16) -> 64788.16
... A369: 46752 | B369: Fri | C369: Dec 2027 | D369: 8208.13 | E369: 6710.99 | F369: 12150.32 | G369: 14409.85 | H369: 15069.5 | I369: 10058.61 | J369: 2446.66 | K369: 14475.32 | L369: 10312.28 | M369: 5388.33 | N369: =SUM(D369:M369) -> 99229.99

Sheet Daily run-rate 2027
A1: Parakeet Café · 2027 daily sales: today's run-rate by month
A2: Each month of today's run-rate by month (Parakeet_2027_Manager_Targets.xlsx) split over its days by the daily model: Prophet (with every special day) and a tree model trained on all stores, blended, retrained on data through Oct 14, 2026. Every month adds up exactly to the monthly figure (see 'Check'). Blue = values from the analysis; black = formulas.
A4: Date | B4: Day | C4: Month | D4: Beverly Hills | E4: Brentwood | F4: Carlsbad | G4: Coronado | H4: Del Mar Café | I4: La Jolla Café | J4: La Jolla Juicery | K4: Little Italy Café | L4: Newport Beach | M4: La Jolla Cove | N4: Total
A5: 46388 | B5: Fri | C5: Jan 2027 | D5: 8205.31 | E5: 7344.99 | F5: 12122.03 | G5: 14246.27 | H5: 15017.08 | I5: 9329.05 | J5: 2323.49 | K5: 13822.99 | L5: 15390.67 | M5: 2185.95 | N5: =SUM(D5:M5) -> 99987.83
A6: 46389 | B6: Sat | C6: Jan 2027 | D6: 8084.87 | E6: 8229.64 | F6: 13015.52 | G6: 15678.16 | H6: 16011.08 | I6: 9827.27 | J6: 2876.28 | K6: 13204.95 | L6: 14127.78 | M6: 2451.84 | N6: =SUM(D6:M6) -> 103507.39
A7: 46390 | B7: Sun | C7: Jan 2027 | D7: 7752.03 | E7: 7547.09 | F7: 11603.36 | G7: 14238.63 | H7: 14611.52 | I7: 8530.69 | J7: 2306.62 | K7: 11068.96 | L7: 13787.13 | M7: 2296.18 | N7: =SUM(D7:M7) -> 93742.21
A8: 46391 | B8: Mon | C8: Jan 2027 | D8: 7429.61 | E8: 5537.13 | F8: 8976.46 | G8: 9044.58 | H8: 10911.97 | I8: 7384.84 | J8: 2015.93 | K8: 7658.13 | L8: 7023.51 | M8: 1216.54 | N8: =SUM(D8:M8) -> 67198.7
A9: 46392 | B9: Tue | C9: Jan 2027 | D9: 7714.68 | E9: 5742.14 | F9: 9031.43 | G9: 8035.08 | H9: 11271.17 | I9: 7332.13 | J9: 2021.37 | K9: 6416.27 | L9: 6711.11 | M9: 1033.45 | N9: =SUM(D9:M9) -> 65308.83
A10: 46393 | B10: Wed | C10: Jan 2027 | D10: 7742.85 | E10: 6053.9 | F10: 9382.81 | G10: 7801.92 | H10: 11769.99 | I10: 7317.61 | J10: 2038.39 | K10: 6449.93 | L10: 6997.68 | M10: 1008.98 | N10: =SUM(D10:M10) -> 66564.06
A11: 46394 | B11: Thu | C11: Jan 2027 | D11: 7695.1 | E11: 6350.16 | F11: 9878.26 | G11: 7972.49 | H11: 12350.69 | I11: 7737.66 | J11: 2168.26 | K11: 6873.46 | L11: 7389.54 | M11: 1122.21 | N11: =SUM(D11:M11) -> 69537.83
A12: 46395 | B12: Fri | C12: Jan 2027 | D12: 7722.28 | E12: 6987.29 | F12: 11183.9 | G12: 9581.33 | H12: 13509.84 | I12: 8384.33 | J12: 2363.04 | K12: 8786.96 | L12: 9029.07 | M12: 1490.05 | N12: =SUM(D12:M12) -> 79038.09
A13: 46396 | B13: Sat | C13: Jan 2027 | D13: 8040.94 | E13: 8992.84 | F13: 13043.25 | G13: 12346.26 | H13: 15983.23 | I13: 9667.99 | J13: 2845.51 | K13: 11345.29 | L13: 14107.02 | M13: 2087.01 | N13: =SUM(D13:M13) -> 98459.34
A14: 46397 | B14: Sun | C14: Jan 2027 | D14: 7930.42 | E14: 8744.12 | F14: 12454.5 | G14: 12004.95 | H14: 15550.36 | I14: 9044.6 | J14: 2434.83 | K14: 10978.15 | L14: 14635.85 | M14: 2098.05 | N14: =SUM(D14:M14) -> 95875.83
A15: 46398 | B15: Mon | C15: Jan 2027 | D15: 7380.6 | E15: 6082.45 | F15: 8911.5 | G15: 6998.91 | H15: 11157.42 | I15: 7419.6 | J15: 1959.79 | K15: 6906.24 | L15: 7405.71 | M15: 1099.02 | N15: =SUM(D15:M15) -> 65321.24
A16: 46399 | B16: Tue | C16: Jan 2027 | D16: 7681.65 | E16: 6255.21 | F16: 8992.16 | G16: 6432.97 | H16: 11661.93 | I16: 7407.83 | J16: 1958.42 | K16: 6161.7 | L16: 7198.21 | M16: 936.79 | N16: =SUM(D16:M16) -> 64686.87
... A369: 46752 | B369: Fri | C369: Dec 2027 | D369: 7245.02 | E369: 5419.17 | F369: 11224.24 | G369: 13044.73 | H369: 14261.55 | I369: 9216.33 | J369: 2310.49 | K369: 12548.15 | L369: 9364.97 | M369: 5388.33 | N369: =SUM(D369:M369) -> 90022.98

Sheet Weekday averages
A1: Average daily sales by weekday and season, 2027 (holidays excluded)
A2: Seasons: summer Jun 15 – Aug 20; holiday season Nov 22 – Jan 5; spring break the week either side of Easter; school term the rest. From the two daily tabs.
A4: Store | B4: Series | C4: Season | D4: Mon | E4: Tue | F4: Wed | G4: Thu | H4: Fri | I4: Sat | J4: Sun
A5: Beverly Hills | B5: Target | C5: School term | D5: 7967.61 | E5: 8263.08 | F5: 8269.04 | G5: 8231.99 | H5: 8326 | I5: 8708.73 | J5: 8606.22
A6: Beverly Hills | B6: Target | C6: Summer | D6: 8419.31 | E6: 8741.66 | F6: 8751.04 | G6: 8641.29 | H6: 8655.38 | I6: 8802.93 | J6: 8812.65
A7: Beverly Hills | B7: Target | C7: Holiday season | D7: 8015.73 | E7: 8267.12 | F7: 8382.85 | G7: 8361.56 | H7: 8475.18 | I7: 8594.82 | J7: 8413.67
A8: Beverly Hills | B8: Run-rate | C8: School term | D8: 7607.84 | E8: 7895.93 | F8: 7918.53 | G8: 7901.56 | H8: 7969.71 | I8: 8314.43 | J8: 8187.14
A9: Beverly Hills | B9: Run-rate | C9: Summer | D9: 7775.57 | E9: 8091.12 | F9: 8099.85 | G9: 7976.19 | H9: 7966.74 | I9: 8112.47 | J9: 8110.7
A10: Beverly Hills | B10: Run-rate | C10: Holiday season | D10: 7267.36 | E10: 7496.57 | F10: 7406.72 | G10: 7380.45 | H10: 7480.74 | I10: 7829.28 | J10: 7659.56
A11: Brentwood | B11: Target | C11: School term | D11: 6444.53 | E11: 6565.64 | F11: 6721.56 | G11: 6786.97 | H11: 7539.78 | I11: 9721.5 | J11: 9443.15
A12: Brentwood | B12: Target | C12: Summer | D12: 6093.44 | E12: 6137.36 | F12: 6252.04 | G12: 6274.69 | H12: 6903.68 | I12: 8822.58 | J12: 8685.02
A13: Brentwood | B13: Target | C13: Holiday season | D13: 6732.7 | E13: 6851.56 | F13: 7029.17 | G13: 7024.2 | H13: 7782.1 | I13: 9735.87 | J13: 9332.69
A14: Brentwood | B14: Run-rate | C14: School term | D14: 5557.74 | E14: 5668.12 | F14: 5815.48 | G14: 5881.84 | H14: 6519.86 | I14: 8392.53 | J14: 8134.09
A15: Brentwood | B15: Run-rate | C15: Summer | D15: 5147.91 | E15: 5192.64 | F15: 5289.98 | G15: 5306.02 | H15: 5832.44 | I15: 7463.58 | J15: 7328.68
A16: Brentwood | B16: Run-rate | C16: Holiday season | D16: 5582.04 | E16: 5682.7 | F16: 5693.92 | G16: 5672.09 | H16: 6284.1 | I16: 8094.79 | J16: 7750.81
... A64: La Jolla Cove | B64: Run-rate | C64: Holiday season | D64: 2703.06 | E64: 2369.45 | F64: 2567.23 | G64: 2797.93 | H64: 3606.01 | I64: 4637.98 | J64: 4611.82

Sheet Check
A1: Check: the daily figures add up to the monthly figures
A2: Monthly targets: 'Targets 2027' in Parakeet_2027_Manager_Targets.xlsx. Run-rate: today's run-rate by month, adding up to 'Reference'. Difference in cents: must be 0.
A3: Total absolute difference (cents) | B3: =SUMPRODUCT(ABS(F6:F284)) -> 0
A5: Store | B5: Series | C5: Month | D5: Monthly figure | E5: Sum of daily | F5: Difference (cents)
A6: Beverly Hills | B6: Target | C6: Jan 2027 | D6: 236300.58 | E6: =SUMIFS('Daily targets 2027'!D$5:D$369,'Daily targets 2027'!$C$5:$C$369,C6) -> 236300.58 | F6: =ROUND(E6*100,0)-ROUND(D6*100,0) -> 0
A7: Beverly Hills | B7: Target | C7: Feb 2027 | D7: 228286.1 | E7: =SUMIFS('Daily targets 2027'!D$5:D$369,'Daily targets 2027'!$C$5:$C$369,C7) -> 228286.1 | F7: =ROUND(E7*100,0)-ROUND(D7*100,0) -> 0
A8: Beverly Hills | B8: Target | C8: Mar 2027 | D8: 253065.97 | E8: =SUMIFS('Daily targets 2027'!D$5:D$369,'Daily targets 2027'!$C$5:$C$369,C8) -> 253065.97 | F8: =ROUND(E8*100,0)-ROUND(D8*100,0) -> 0
A9: Beverly Hills | B9: Target | C9: Apr 2027 | D9: 244024.03 | E9: =SUMIFS('Daily targets 2027'!D$5:D$369,'Daily targets 2027'!$C$5:$C$369,C9) -> 244024.03 | F9: =ROUND(E9*100,0)-ROUND(D9*100,0) -> 0
A10: Beverly Hills | B10: Target | C10: May 2027 | D10: 267870.67 | E10: =SUMIFS('Daily targets 2027'!D$5:D$369,'Daily targets 2027'!$C$5:$C$369,C10) -> 267870.67 | F10: =ROUND(E10*100,0)-ROUND(D10*100,0) -> 0
A11: Beverly Hills | B11: Target | C11: Jun 2027 | D11: 259346.7 | E11: =SUMIFS('Daily targets 2027'!D$5:D$369,'Daily targets 2027'!$C$5:$C$369,C11) -> 259346.7 | F11: =ROUND(E11*100,0)-ROUND(D11*100,0) -> 0
A12: Beverly Hills | B12: Target | C12: Jul 2027 | D12: 264681.78 | E12: =SUMIFS('Daily targets 2027'!D$5:D$369,'Daily targets 2027'!$C$5:$C$369,C12) -> 264681.78 | F12: =ROUND(E12*100,0)-ROUND(D12*100,0) -> 0
A13: Beverly Hills | B13: Target | C13: Aug 2027 | D13: 277020.97 | E13: =SUMIFS('Daily targets 2027'!D$5:D$369,'Daily targets 2027'!$C$5:$C$369,C13) -> 277020.97 | F13: =ROUND(E13*100,0)-ROUND(D13*100,0) -> 0
A14: Beverly Hills | B14: Target | C14: Sep 2027 | D14: 252137.81 | E14: =SUMIFS('Daily targets 2027'!D$5:D$369,'Daily targets 2027'!$C$5:$C$369,C14) -> 252137.81 | F14: =ROUND(E14*100,0)-ROUND(D14*100,0) -> 0
A15: Beverly Hills | B15: Target | C15: Oct 2027 | D15: 260857.38 | E15: =SUMIFS('Daily targets 2027'!D$5:D$369,'Daily targets 2027'!$C$5:$C$369,C15) -> 260857.38 | F15: =ROUND(E15*100,0)-ROUND(D15*100,0) -> 0
A16: Beverly Hills | B16: Target | C16: Nov 2027 | D16: 262324.76 | E16: =SUMIFS('Daily targets 2027'!D$5:D$369,'Daily targets 2027'!$C$5:$C$369,C16) -> 262324.76 | F16: =ROUND(E16*100,0)-ROUND(D16*100,0) -> 0
A17: Beverly Hills | B17: Target | C17: Dec 2027 | D17: 261120.25 | E17: =SUMIFS('Daily targets 2027'!D$5:D$369,'Daily targets 2027'!$C$5:$C$369,C17) -> 261120.25 | F17: =ROUND(E17*100,0)-ROUND(D17*100,0) -> 0
A18: Beverly Hills | B18: Target | C18: Year | D18: =SUM(D6:D17) -> 3067037 | E18: =SUM(E6:E17) -> 3067037 | F18: =ROUND(E18*100,0)-ROUND(D18*100,0) -> 0
A20: Brentwood | B20: Target | C20: Jan 2027 | D20: 235613.92 | E20: =SUMIFS('Daily targets 2027'!E$5:E$369,'Daily targets 2027'!$C$5:$C$369,C20) -> 235613.92 | F20: =ROUND(E20*100,0)-ROUND(D20*100,0) -> 0
A21: Brentwood | B21: Target | C21: Feb 2027 | D21: 211374.03 | E21: =SUMIFS('Daily targets 2027'!E$5:E$369,'Daily targets 2027'!$C$5:$C$369,C21) -> 211374.03 | F21: =ROUND(E21*100,0)-ROUND(D21*100,0) -> 0
A22: Brentwood | B22: Target | C22: Mar 2027 | D22: 230585.93 | E22: =SUMIFS('Daily targets 2027'!E$5:E$369,'Daily targets 2027'!$C$5:$C$369,C22) -> 230585.93 | F22: =ROUND(E22*100,0)-ROUND(D22*100,0) -> 0
A23: Brentwood | B23: Target | C23: Apr 2027 | D23: 221906.4 | E23: =SUMIFS('Daily targets 2027'!E$5:E$369,'Daily targets 2027'!$C$5:$C$369,C23) -> 221906.4 | F23: =ROUND(E23*100,0)-ROUND(D23*100,0) -> 0
A24: Brentwood | B24: Target | C24: May 2027 | D24: 238538.56 | E24: =SUMIFS('Daily targets 2027'!E$5:E$369,'Daily targets 2027'!$C$5:$C$369,C24) -> 238538.56 | F24: =ROUND(E24*100,0)-ROUND(D24*100,0) -> 0
A25: Brentwood | B25: Target | C25: Jun 2027 | D25: 212054.56 | E25: =SUMIFS('Daily targets 2027'!E$5:E$369,'Daily targets 2027'!$C$5:$C$369,C25) -> 212054.56 | F25: =ROUND(E25*100,0)-ROUND(D25*100,0) -> 0
A26: Brentwood | B26: Target | C26: Jul 2027 | D26: 212957.45 | E26: =SUMIFS('Daily targets 2027'!E$5:E$369,'Daily targets 2027'!$C$5:$C$369,C26) -> 212957.45 | F26: =ROUND(E26*100,0)-ROUND(D26*100,0) -> 0
A27: Brentwood | B27: Target | C27: Aug 2027 | D27: 223987.93 | E27: =SUMIFS('Daily targets 2027'!E$5:E$369,'Daily targets 2027'!$C$5:$C$369,C27) -> 223987.93 | F27: =ROUND(E27*100,0)-ROUND(D27*100,0) -> 0
A28: Brentwood | B28: Target | C28: Sep 2027 | D28: 222999.83 | E28: =SUMIFS('Daily targets 2027'!E$5:E$369,'Daily targets 2027'!$C$5:$C$369,C28) -> 222999.83 | F28: =ROUND(E28*100,0)-ROUND(D28*100,0) -> 0
A29: Brentwood | B29: Target | C29: Oct 2027 | D29: 246998.08 | E29: =SUMIFS('Daily targets 2027'!E$5:E$369,'Daily targets 2027'!$C$5:$C$369,C29) -> 246998.08 | F29: =ROUND(E29*100,0)-ROUND(D29*100,0) -> 0
A30: Brentwood | B30: Target | C30: Nov 2027 | D30: 246642.42 | E30: =SUMIFS('Daily targets 2027'!E$5:E$369,'Daily targets 2027'!$C$5:$C$369,C30) -> 246642.42 | F30: =ROUND(E30*100,0)-ROUND(D30*100,0) -> 0
A31: Brentwood | B31: Target | C31: Dec 2027 | D31: 234758.89 | E31: =SUMIFS('Daily targets 2027'!E$5:E$369,'Daily targets 2027'!$C$5:$C$369,C31) -> 234758.89 | F31: =ROUND(E31*100,0)-ROUND(D31*100,0) -> 0
A32: Brentwood | B32: Target | C32: Year | D32: =SUM(D20:D31) -> 2738418 | E32: =SUM(E20:E31) -> 2738418 | F32: =ROUND(E32*100,0)-ROUND(D32*100,0) -> 0
A34: Carlsbad | B34: Target | C34: Jan 2027 | D34: 327389.23 | E34: =SUMIFS('Daily targets 2027'!F$5:F$369,'Daily targets 2027'!$C$5:$C$369,C34) -> 327389.23 | F34: =ROUND(E34*100,0)-ROUND(D34*100,0) -> 0
A35: Carlsbad | B35: Target | C35: Feb 2027 | D35: 286557.65 | E35: =SUMIFS('Daily targets 2027'!F$5:F$369,'Daily targets 2027'!$C$5:$C$369,C35) -> 286557.65 | F35: =ROUND(E35*100,0)-ROUND(D35*100,0) -> 0
A36: Carlsbad | B36: Target | C36: Mar 2027 | D36: 330123.97 | E36: =SUMIFS('Daily targets 2027'!F$5:F$369,'Daily targets 2027'!$C$5:$C$369,C36) -> 330123.97 | F36: =ROUND(E36*100,0)-ROUND(D36*100,0) -> 0
A37: Carlsbad | B37: Target | C37: Apr 2027 | D37: 335065.58 | E37: =SUMIFS('Daily targets 2027'!F$5:F$369,'Daily targets 2027'!$C$5:$C$369,C37) -> 335065.58 | F37: =ROUND(E37*100,0)-ROUND(D37*100,0) -> 0
A38: Carlsbad | B38: Target | C38: May 2027 | D38: 359826.7 | E38: =SUMIFS('Daily targets 2027'!F$5:F$369,'Daily targets 2027'!$C$5:$C$369,C38) -> 359826.7 | F38: =ROUND(E38*100,0)-ROUND(D38*100,0) -> 0
A39: Carlsbad | B39: Target | C39: Jun 2027 | D39: 327452.91 | E39: =SUMIFS('Daily targets 2027'!F$5:F$369,'Daily targets 2027'!$C$5:$C$369,C39) -> 327452.91 | F39: =ROUND(E39*100,0)-ROUND(D39*100,0) -> 0
A40: Carlsbad | B40: Target | C40: Jul 2027 | D40: 349039.01 | E40: =SUMIFS('Daily targets 2027'!F$5:F$369,'Daily targets 2027'!$C$5:$C$369,C40) -> 349039.01 | F40: =ROUND(E40*100,0)-ROUND(D40*100,0) -> 0
A41: Carlsbad | B41: Target | C41: Aug 2027 | D41: 341442.95 | E41: =SUMIFS('Daily targets 2027'!F$5:F$369,'Daily targets 2027'!$C$5:$C$369,C41) -> 341442.95 | F41: =ROUND(E41*100,0)-ROUND(D41*100,0) -> 0
A42: Carlsbad | B42: Target | C42: Sep 2027 | D42: 306814.01 | E42: =SUMIFS('Daily targets 2027'!F$5:F$369,'Daily targets 2027'!$C$5:$C$369,C42) -> 306814.01 | F42: =ROUND(E42*100,0)-ROUND(D42*100,0) -> 0
A43: Carlsbad | B43: Target | C43: Oct 2027 | D43: 324227.5 | E43: =SUMIFS('Daily targets 2027'!F$5:F$369,'Daily targets 2027'!$C$5:$C$369,C43) -> 324227.5 | F43: =ROUND(E43*100,0)-ROUND(D43*100,0) -> 0
...

Sheet Notes
A1: How the daily figures are built
A3: Monthly and annual figures: exactly those in the targets workbook and deck (targets: each store's objective in the October 15 budget, along our most accurate forecast; run-rate: today's run-rate by month); this file only splits each month into its days.
A4: Daily model: the geometric mean of two models, both retrained on all data through Oct 14, 2026: Prophet with the adopted settings (time of year, day of week, holidays) plus the other special days (Dec 26, the days between Christmas and New Year's Eve, Thanksgiving weekend, spring break, Halloween), and a tree model (LightGBM) trained on all ten stores together on each day's sales against its month's average, from the weekday, season, special days and time of year, with recent days weighing more.
A5: Chosen by backtest: six forecast origins (Dec 2024 to Mar 2026), each month of the next year split into days and compared with actual days, given the true month. Daily error: Prophet as tuned 9.2%, this blend 8.5%; on days-off holidays 12.8% and 11.8%. Tested and not used: weekly patterns by season or for recent months in Prophet, seasonality within the month, holidays set to their usual level, and the café and delivery modelled apart.
A6: Beverly Hills: its daily shape is pulled halfway toward equal days. Its weekly pattern has been flattening every year (weekends about +30% over weekdays in 2024, +20-25% in 2025, about 0% in 2026), so the learned shape overshoots; halfway cut its backtest error from 12.0% to 10.3%, in 2025 and in 2026.
A7: Each month is split in cents in proportion to the model's days; amounts are rounded so the month adds up exactly (see 'Check').
A8: Holidays the stores have always traded on are kept as trading days; a café closure that is not in the calendar will show up as a shortfall on that day.
