Workbook

Sheet Daily run-rate 2026
A1: Parakeet Café · daily sales at today's run-rate, Oct 15 – Dec 31, 2026
A2: Today's run-rate (the last 45 days of Toast sales, Aug 31 – Oct 14, seasonally adjusted and held flat) for the rest of 2026, by month as in the run-rate deck, split over the days by the daily model (Prophet with every special day and a tree model trained on all stores, blended, retrained through Oct 14, 2026). Every month adds up exactly to its monthly figure (see 'Check'). Blue = values from the analysis; black = formulas.
A4: Date | B4: Day | C4: Month | D4: Beverly Hills | E4: Brentwood | F4: Carlsbad | G4: Coronado | H4: Del Mar Café | I4: La Jolla Café | J4: La Jolla Juicery | K4: Little Italy Café | L4: Newport Beach | M4: La Jolla Cove | N4: Total
A5: 46310 | B5: Thu | C5: Oct 2026 | D5: 7590.6 | E5: 5708.64 | F5: 8990.13 | G5: 7888.13 | H5: 11810.22 | I5: 7571.96 | J5: 2088.05 | K5: 7590.42 | L5: 6885.19 | M5: 1408.31 | N5: =SUM(D5:M5) -> 67531.65
A6: 46311 | B6: Fri | C6: Oct 2026 | D6: 7707.55 | E6: 6354.16 | F6: 10330.92 | G6: 9825.16 | H6: 13177.63 | I6: 8322.84 | J6: 2280.62 | K6: 9703.12 | L6: 8403.33 | M6: 1877.17 | N6: =SUM(D6:M6) -> 77982.5
A7: 46312 | B7: Sat | C7: Oct 2026 | D7: 8185.74 | E7: 8421.24 | F7: 12008.52 | G7: 13019.4 | H7: 15393.19 | I7: 9516.23 | J7: 2793.38 | K7: 12469.01 | L7: 13111.65 | M7: 2509.92 | N7: =SUM(D7:M7) -> 97428.28
A8: 46313 | B8: Sun | C8: Oct 2026 | D8: 8035.3 | E8: 8212.62 | F8: 11423.25 | G8: 12956.52 | H8: 15070.27 | I8: 8982.97 | J8: 2415.91 | K8: 12315.82 | L8: 13718.06 | M8: 2537.04 | N8: =SUM(D8:M8) -> 95667.76
A9: 46314 | B9: Mon | C9: Oct 2026 | D9: 7092.48 | E9: 5242.72 | F9: 7744.44 | G9: 7663.5 | H9: 10036.14 | I9: 6969.65 | J9: 1990.71 | K9: 7400.67 | L9: 6483.46 | M9: 1376.53 | N9: =SUM(D9:M9) -> 62000.3
A10: 46315 | B10: Tue | C10: Oct 2026 | D10: 7290.95 | E10: 5174.83 | F10: 7668.09 | G10: 6887.88 | H10: 10338.79 | I10: 6813.91 | J10: 1962.8 | K10: 6159.31 | L10: 6105.04 | M10: 1163.69 | N10: =SUM(D10:M10) -> 59565.29
A11: 46316 | B11: Wed | C11: Oct 2026 | D11: 7395.02 | E11: 5439.85 | F11: 8223.93 | G11: 7281.82 | H11: 11112.21 | I11: 6865.51 | J11: 2035.4 | K11: 6423.97 | L11: 6487.54 | M11: 1169.26 | N11: =SUM(D11:M11) -> 62434.51
A12: 46317 | B12: Thu | C12: Oct 2026 | D12: 7398.55 | E12: 5560.61 | F12: 8583.33 | G12: 7596.15 | H12: 11625.11 | I12: 7195.16 | J12: 2099.02 | K12: 6823.65 | L12: 6860.95 | M12: 1369.15 | N12: =SUM(D12:M12) -> 65111.68
A13: 46318 | B13: Fri | C13: Oct 2026 | D13: 7512.36 | E13: 6245.01 | F13: 10006.89 | G13: 9393.82 | H13: 12886.31 | I13: 7950.49 | J13: 2254.3 | K13: 8687.48 | L13: 8232.33 | M13: 1776.49 | N13: =SUM(D13:M13) -> 74945.48
A14: 46319 | B14: Sat | C14: Oct 2026 | D14: 7985.36 | E14: 8346.19 | F14: 11837.38 | G14: 12575.95 | H14: 14966.27 | I14: 9068.42 | J14: 2713.14 | K14: 11132.26 | L14: 12997.22 | M14: 2391.96 | N14: =SUM(D14:M14) -> 94014.15
A15: 46320 | B15: Sun | C15: Oct 2026 | D15: 7824.53 | E15: 8117.5 | F15: 11137.3 | G15: 12130.21 | H15: 14337.18 | I15: 8311.59 | J15: 2286.76 | K15: 10298.69 | L15: 13383.97 | M15: 2314.55 | N15: =SUM(D15:M15) -> 90142.28
A16: 46321 | B16: Mon | C16: Oct 2026 | D16: 7086.96 | E16: 5526.34 | F16: 8103.06 | G16: 7576.41 | H16: 10091.75 | I16: 6839.69 | J16: 2041.33 | K16: 6664.99 | L16: 6620.12 | M16: 1276.62 | N16: =SUM(D16:M16) -> 61827.27
... A82: 46387 | B82: Thu | C82: Dec 2026 | D82: 6530.71 | E82: 4989.06 | F82: 9143.57 | G82: 10150.62 | H82: 11698.78 | I82: 7687.28 | J82: 1830.33 | K82: 9810.5 | L82: 6933.79 | M82: 1560.49 | N82: =SUM(D82:M82) -> 70335.13

Sheet Check
A1: Check: the daily figures add up to the run-rate by month
A2: Monthly figures: today's run-rate for Oct 15-31, November and December 2026, adding up to the deck's 'Oct 15 – Dec 31 at run-rate'. Difference in cents: must be 0.
A3: Total absolute difference (cents) | B3: =SUMPRODUCT(ABS(E6:E54)) -> 0
A5: Store | B5: Period | C5: Monthly figure | D5: Sum of daily | E5: Difference (cents)
A6: Beverly Hills | B6: Oct 15–31, 2026 | C6: 128424.84 | D6: =SUMIFS('Daily run-rate 2026'!D$5:D$82,'Daily run-rate 2026'!$C$5:$C$82,"Oct 2026") -> 128424.84 | E6: =ROUND(D6*100,0)-ROUND(C6*100,0) -> 0
A7: Beverly Hills | B7: November 2026 | C7: 233324.58 | D7: =SUMIFS('Daily run-rate 2026'!D$5:D$82,'Daily run-rate 2026'!$C$5:$C$82,"Nov 2026") -> 233324.58 | E7: =ROUND(D7*100,0)-ROUND(C7*100,0) -> 0
A8: Beverly Hills | B8: December 2026 | C8: 226008.87 | D8: =SUMIFS('Daily run-rate 2026'!D$5:D$82,'Daily run-rate 2026'!$C$5:$C$82,"Dec 2026") -> 226008.87 | E8: =ROUND(D8*100,0)-ROUND(C8*100,0) -> 0
A9: Beverly Hills | B9: Oct 15 – Dec 31 | C9: =SUM(C6:C8) -> 587758.29 | D9: =SUM(D6:D8) -> 587758.29 | E9: =ROUND(D9*100,0)-ROUND(C9*100,0) -> 0
A11: Brentwood | B11: Oct 15–31, 2026 | C11: 110767.36 | D11: =SUMIFS('Daily run-rate 2026'!E$5:E$82,'Daily run-rate 2026'!$C$5:$C$82,"Oct 2026") -> 110767.36 | E11: =ROUND(D11*100,0)-ROUND(C11*100,0) -> 0
A12: Brentwood | B12: November 2026 | C12: 204194.31 | D12: =SUMIFS('Daily run-rate 2026'!E$5:E$82,'Daily run-rate 2026'!$C$5:$C$82,"Nov 2026") -> 204194.31 | E12: =ROUND(D12*100,0)-ROUND(C12*100,0) -> 0
A13: Brentwood | B13: December 2026 | C13: 189139.72 | D13: =SUMIFS('Daily run-rate 2026'!E$5:E$82,'Daily run-rate 2026'!$C$5:$C$82,"Dec 2026") -> 189139.72 | E13: =ROUND(D13*100,0)-ROUND(C13*100,0) -> 0
A14: Brentwood | B14: Oct 15 – Dec 31 | C14: =SUM(C11:C13) -> 504101.39 | D14: =SUM(D11:D13) -> 504101.39 | E14: =ROUND(D14*100,0)-ROUND(C14*100,0) -> 0
A16: Carlsbad | B16: Oct 15–31, 2026 | C16: 163627.69 | D16: =SUMIFS('Daily run-rate 2026'!F$5:F$82,'Daily run-rate 2026'!$C$5:$C$82,"Oct 2026") -> 163627.69 | E16: =ROUND(D16*100,0)-ROUND(C16*100,0) -> 0
A17: Carlsbad | B17: November 2026 | C17: 313937.69 | D17: =SUMIFS('Daily run-rate 2026'!F$5:F$82,'Daily run-rate 2026'!$C$5:$C$82,"Nov 2026") -> 313937.69 | E17: =ROUND(D17*100,0)-ROUND(C17*100,0) -> 0
A18: Carlsbad | B18: December 2026 | C18: 336469.7 | D18: =SUMIFS('Daily run-rate 2026'!F$5:F$82,'Daily run-rate 2026'!$C$5:$C$82,"Dec 2026") -> 336469.7 | E18: =ROUND(D18*100,0)-ROUND(C18*100,0) -> 0
A19: Carlsbad | B19: Oct 15 – Dec 31 | C19: =SUM(C16:C18) -> 814035.08 | D19: =SUM(D16:D18) -> 814035.08 | E19: =ROUND(D19*100,0)-ROUND(C19*100,0) -> 0
A21: Coronado | B21: Oct 15–31, 2026 | C21: 157673.5 | D21: =SUMIFS('Daily run-rate 2026'!G$5:G$82,'Daily run-rate 2026'!$C$5:$C$82,"Oct 2026") -> 157673.5 | E21: =ROUND(D21*100,0)-ROUND(C21*100,0) -> 0
A22: Coronado | B22: November 2026 | C22: 277753.24 | D22: =SUMIFS('Daily run-rate 2026'!G$5:G$82,'Daily run-rate 2026'!$C$5:$C$82,"Nov 2026") -> 277753.24 | E22: =ROUND(D22*100,0)-ROUND(C22*100,0) -> 0
A23: Coronado | B23: December 2026 | C23: 304316.93 | D23: =SUMIFS('Daily run-rate 2026'!G$5:G$82,'Daily run-rate 2026'!$C$5:$C$82,"Dec 2026") -> 304316.93 | E23: =ROUND(D23*100,0)-ROUND(C23*100,0) -> 0
A24: Coronado | B24: Oct 15 – Dec 31 | C24: =SUM(C21:C23) -> 739743.67 | D24: =SUM(D21:D23) -> 739743.67 | E24: =ROUND(D24*100,0)-ROUND(C24*100,0) -> 0
A26: Del Mar Café | B26: Oct 15–31, 2026 | C26: 210956.77 | D26: =SUMIFS('Daily run-rate 2026'!H$5:H$82,'Daily run-rate 2026'!$C$5:$C$82,"Oct 2026") -> 210956.77 | E26: =ROUND(D26*100,0)-ROUND(C26*100,0) -> 0
A27: Del Mar Café | B27: November 2026 | C27: 376945.29 | D27: =SUMIFS('Daily run-rate 2026'!H$5:H$82,'Daily run-rate 2026'!$C$5:$C$82,"Nov 2026") -> 376945.29 | E27: =ROUND(D27*100,0)-ROUND(C27*100,0) -> 0
A28: Del Mar Café | B28: December 2026 | C28: 403870.34 | D28: =SUMIFS('Daily run-rate 2026'!H$5:H$82,'Daily run-rate 2026'!$C$5:$C$82,"Dec 2026") -> 403870.34 | E28: =ROUND(D28*100,0)-ROUND(C28*100,0) -> 0
A29: Del Mar Café | B29: Oct 15 – Dec 31 | C29: =SUM(C26:C28) -> 991772.4 | D29: =SUM(D26:D28) -> 991772.4 | E29: =ROUND(D29*100,0)-ROUND(C29*100,0) -> 0
A31: La Jolla Café | B31: Oct 15–31, 2026 | C31: 131112.72 | D31: =SUMIFS('Daily run-rate 2026'!I$5:I$82,'Daily run-rate 2026'!$C$5:$C$82,"Oct 2026") -> 131112.72 | E31: =ROUND(D31*100,0)-ROUND(C31*100,0) -> 0
A32: La Jolla Café | B32: November 2026 | C32: 234003.42 | D32: =SUMIFS('Daily run-rate 2026'!I$5:I$82,'Daily run-rate 2026'!$C$5:$C$82,"Nov 2026") -> 234003.42 | E32: =ROUND(D32*100,0)-ROUND(C32*100,0) -> 0
A33: La Jolla Café | B33: December 2026 | C33: 242281.78 | D33: =SUMIFS('Daily run-rate 2026'!I$5:I$82,'Daily run-rate 2026'!$C$5:$C$82,"Dec 2026") -> 242281.78 | E33: =ROUND(D33*100,0)-ROUND(C33*100,0) -> 0
A34: La Jolla Café | B34: Oct 15 – Dec 31 | C34: =SUM(C31:C33) -> 607397.92 | D34: =SUM(D31:D33) -> 607397.92 | E34: =ROUND(D34*100,0)-ROUND(C34*100,0) -> 0
A36: La Jolla Juicery | B36: Oct 15–31, 2026 | C36: 37989.46 | D36: =SUMIFS('Daily run-rate 2026'!J$5:J$82,'Daily run-rate 2026'!$C$5:$C$82,"Oct 2026") -> 37989.46 | E36: =ROUND(D36*100,0)-ROUND(C36*100,0) -> 0
A37: La Jolla Juicery | B37: November 2026 | C37: 63561.22 | D37: =SUMIFS('Daily run-rate 2026'!J$5:J$82,'Daily run-rate 2026'!$C$5:$C$82,"Nov 2026") -> 63561.22 | E37: =ROUND(D37*100,0)-ROUND(C37*100,0) -> 0
A38: La Jolla Juicery | B38: December 2026 | C38: 63536.28 | D38: =SUMIFS('Daily run-rate 2026'!J$5:J$82,'Daily run-rate 2026'!$C$5:$C$82,"Dec 2026") -> 63536.28 | E38: =ROUND(D38*100,0)-ROUND(C38*100,0) -> 0
A39: La Jolla Juicery | B39: Oct 15 – Dec 31 | C39: =SUM(C36:C38) -> 165086.96 | D39: =SUM(D36:D38) -> 165086.96 | E39: =ROUND(D39*100,0)-ROUND(C39*100,0) -> 0
A41: Little Italy Café | B41: Oct 15–31, 2026 | C41: 142428.47 | D41: =SUMIFS('Daily run-rate 2026'!K$5:K$82,'Daily run-rate 2026'!$C$5:$C$82,"Oct 2026") -> 142428.47 | E41: =ROUND(D41*100,0)-ROUND(C41*100,0) -> 0
A42: Little Italy Café | B42: November 2026 | C42: 257206.19 | D42: =SUMIFS('Daily run-rate 2026'!K$5:K$82,'Daily run-rate 2026'!$C$5:$C$82,"Nov 2026") -> 257206.19 | E42: =ROUND(D42*100,0)-ROUND(C42*100,0) -> 0
A43: Little Italy Café | B43: December 2026 | C43: 253587.72 | D43: =SUMIFS('Daily run-rate 2026'!K$5:K$82,'Daily run-rate 2026'!$C$5:$C$82,"Dec 2026") -> 253587.72 | E43: =ROUND(D43*100,0)-ROUND(C43*100,0) -> 0
A44: Little Italy Café | B44: Oct 15 – Dec 31 | C44: =SUM(C41:C43) -> 653222.38 | D44: =SUM(D41:D43) -> 653222.38 | E44: =ROUND(D44*100,0)-ROUND(C44*100,0) -> 0
A46: Newport Beach | B46: Oct 15–31, 2026 | C46: 148914.46 | D46: =SUMIFS('Daily run-rate 2026'!L$5:L$82,'Daily run-rate 2026'!$C$5:$C$82,"Oct 2026") -> 148914.46 | E46: =ROUND(D46*100,0)-ROUND(C46*100,0) -> 0
A47: Newport Beach | B47: November 2026 | C47: 269354.91 | D47: =SUMIFS('Daily run-rate 2026'!L$5:L$82,'Daily run-rate 2026'!$C$5:$C$82,"Nov 2026") -> 269354.91 | E47: =ROUND(D47*100,0)-ROUND(C47*100,0) -> 0
A48: Newport Beach | B48: December 2026 | C48: 276457.9 | D48: =SUMIFS('Daily run-rate 2026'!L$5:L$82,'Daily run-rate 2026'!$C$5:$C$82,"Dec 2026") -> 276457.9 | E48: =ROUND(D48*100,0)-ROUND(C48*100,0) -> 0
A49: Newport Beach | B49: Oct 15 – Dec 31 | C49: =SUM(C46:C48) -> 694727.27 | D49: =SUM(D46:D48) -> 694727.27 | E49: =ROUND(D49*100,0)-ROUND(C49*100,0) -> 0
...

Sheet Notes
A1: How the daily figures are built
A3: Monthly figures: today's run-rate as in the run-rate deck (Part 1): October 1-14 is actual sales, so October here is only Oct 15-31; November and December are whole months. The three add up to the deck's 'Oct 15 – Dec 31 at run-rate' for each café.
A4: Daily model: the same as for the 2027 daily targets, retrained on all data through Oct 14, 2026 (see the Notes tab of Parakeet_2027_Daily_Targets.xlsx): Prophet with every special day (Thanksgiving weekend, Christmas week, Dec 26, Halloween...) and a tree model trained on all ten stores, blended; Beverly Hills halfway to equal days.
A5: Each month is split in cents in proportion to the model's days, so the month adds up exactly (see 'Check'). Closed days (as in the run-rate) get no sales.
A6: The run-rate assumes no further growth from today's level: a café still growing will run ahead of these days.
