Workbook

Sheet Targets 2027
A1: Parakeet Café · 2027 sales targets by store
A2: Net sales targets per month (our plan; La Jolla Cove switches to the budget's remodeled rate from its Oct 1, 2027 reopening). Blue = values from the analysis; black = formulas.
A4: Store | B4: Jan 2027 | C4: Feb 2027 | D4: Mar 2027 | E4: Apr 2027 | F4: May 2027 | G4: Jun 2027 | H4: Jul 2027 | I4: Aug 2027 | J4: Sep 2027 | K4: Oct 2027 | L4: Nov 2027 | M4: Dec 2027 | N4: Q1 | O4: Q2 | P4: Q3 | Q4: Q4 | R4: Total 2027 | S4: 2026 finish (run-rate) | T4: Growth
A5: Beverly Hills | B5: 240335.44 | C5: 232184.11 | D5: 257387.11 | E5: 248190.77 | F5: 272444.59 | G5: 263775.07 | H5: 269201.25 | I5: 281751.13 | J5: 256443.1 | K5: 265311.55 | L5: 266803.98 | M5: 265578.91 | N5: =SUM(B5:D5) -> 729906.66 | O5: =SUM(E5:G5) -> 784410.43 | P5: =SUM(H5:J5) -> 807395.48 | Q5: =SUM(K5:M5) -> 797694.44 | R5: =SUM(B5:M5) -> 3119407 | S5: 2606461.4 | T5: =IF(S5=0,"",R5/S5-1) -> 0.19679772
A6: Brentwood | B6: 227289.23 | C6: 203905.78 | D6: 222438.88 | E6: 214066.03 | F6: 230110.53 | G6: 204562.27 | H6: 205433.25 | I6: 216074.01 | J6: 215120.82 | K6: 238271.16 | L6: 237928.07 | M6: 226464.41 | N6: =SUM(B6:D6) -> 653633.89 | O6: =SUM(E6:G6) -> 648738.83 | P6: =SUM(H6:J6) -> 636628.08 | Q6: =SUM(K6:M6) -> 702663.64 | R6: =SUM(B6:M6) -> 2641664.4 | S6: 2302939.3 | T6: =IF(S6=0,"",R6/S6-1) -> 0.14708385
A7: Carlsbad | B7: 347155.87 | C7: 303859.01 | D7: 350055.72 | E7: 355295.68 | F7: 381551.8 | G7: 347223.39 | H7: 370112.79 | I7: 362058.09 | J7: 325338.38 | K7: 343803.24 | L7: 356440.28 | M7: 390772.6 | N7: =SUM(B7:D7) -> 1001070.6 | O7: =SUM(E7:G7) -> 1084070.9 | P7: =SUM(H7:J7) -> 1057509.3 | Q7: =SUM(K7:M7) -> 1091016.1 | R7: =SUM(B7:M7) -> 4233666.8 | S7: 3723643.2 | T7: =IF(S7=0,"",R7/S7-1) -> 0.136969
A8: Coronado | B8: 312399.46 | C8: 281595.6 | D8: 362333.45 | E8: 356921.7 | F8: 376891.75 | G8: 378275.27 | H8: 516508.85 | I8: 427274.35 | J8: 310518.86 | K8: 327674.08 | L8: 306577.59 | M8: 350719.75 | N8: =SUM(B8:D8) -> 956328.51 | O8: =SUM(E8:G8) -> 1112088.7 | P8: =SUM(H8:J8) -> 1254302.1 | Q8: =SUM(K8:M8) -> 984971.42 | R8: =SUM(B8:M8) -> 4307690.7 | S8: 3987463.8 | T8: =IF(S8=0,"",R8/S8-1) -> 0.080308415
A9: Del Mar Café | B9: 430949.59 | C9: 383310.31 | D9: 438484.65 | E9: 416409.53 | F9: 454594.01 | G9: 421443.45 | H9: 444464.45 | I9: 462061.08 | J9: 403897.6 | K9: 425684.45 | L9: 416009.75 | M9: 453974.83 | N9: =SUM(B9:D9) -> 1252744.6 | O9: =SUM(E9:G9) -> 1292447 | P9: =SUM(H9:J9) -> 1310423.1 | Q9: =SUM(K9:M9) -> 1295669 | R9: =SUM(B9:M9) -> 5151283.7 | S9: 4665803.1 | T9: =IF(S9=0,"",R9/S9-1) -> 0.10405082
A10: La Jolla Café | B10: 257347.15 | C10: 234138.23 | D10: 265056.56 | E10: 262039.19 | F10: 279695.99 | G10: 254919.15 | H10: 278642.95 | I10: 278428.66 | J10: 244515.81 | K10: 257847.21 | L10: 250121.21 | M10: 264806 | N10: =SUM(B10:D10) -> 756541.94 | O10: =SUM(E10:G10) -> 796654.33 | P10: =SUM(H10:J10) -> 801587.42 | Q10: =SUM(K10:M10) -> 772774.42 | R10: =SUM(B10:M10) -> 3127558.1 | S10: 2904088.3 | T10: =IF(S10=0,"",R10/S10-1) -> 0.076950074
A11: La Jolla Juicery | B11: 70024.33 | C11: 65363.47 | D11: 80282.84 | E11: 78691.41 | F11: 81914.6 | G11: 80680.83 | H11: 95117.93 | I11: 92412.44 | J11: 75560.91 | K11: 74362.39 | L11: 67804.32 | M11: 69510.22 | N11: =SUM(B11:D11) -> 215670.64 | O11: =SUM(E11:G11) -> 241286.84 | P11: =SUM(H11:J11) -> 263091.28 | Q11: =SUM(K11:M11) -> 211676.93 | R11: =SUM(B11:M11) -> 931725.69 | S11: 891089.16 | T11: =IF(S11=0,"",R11/S11-1) -> 0.045603214
A12: Little Italy Café | B12: 296914.31 | C12: 286294.25 | D12: 338579.82 | E12: 342033.7 | F12: 347090.01 | G12: 332147.99 | H12: 367354.16 | I12: 368327.3 | J12: 307233.84 | K12: 316289.17 | L12: 306667.72 | M12: 319163.66 | N12: =SUM(B12:D12) -> 921788.38 | O12: =SUM(E12:G12) -> 1021271.7 | P12: =SUM(H12:J12) -> 1042915.3 | Q12: =SUM(K12:M12) -> 942120.55 | R12: =SUM(B12:M12) -> 3928095.9 | S12: 3248637.5 | T12: =IF(S12=0,"",R12/S12-1) -> 0.20915183
A13: Newport Beach | B13: 327146.38 | C13: 271492.7 | D13: 316609.81 | E13: 307133.63 | F13: 349631.07 | G13: 326325.44 | H13: 363061.05 | I13: 359674.68 | J13: 296046.26 | K13: 317470.65 | L13: 297737.89 | M13: 322139.38 | N13: =SUM(B13:D13) -> 915248.89 | O13: =SUM(E13:G13) -> 983090.14 | P13: =SUM(H13:J13) -> 1018782 | Q13: =SUM(K13:M13) -> 937347.92 | R13: =SUM(B13:M13) -> 3854468.9 | S13: 3464416.6 | T13: =IF(S13=0,"",R13/S13-1) -> 0.11258817
A14: Nine existing cafés | B14: =SUM(B5:B13) -> 2509561.8 | C14: =SUM(C5:C13) -> 2262143.5 | D14: =SUM(D5:D13) -> 2631228.8 | E14: =SUM(E5:E13) -> 2580781.6 | F14: =SUM(F5:F13) -> 2773924.4 | G14: =SUM(G5:G13) -> 2609352.9 | H14: =SUM(H5:H13) -> 2909896.7 | I14: =SUM(I5:I13) -> 2848061.7 | ... S14: =SUM(S5:S13) -> 27794542 | T14: =IF(S14=0,"",R14/S14-1) -> 0.12596067
A15: La Jolla Cove | B15: 49132.16 | C15: 47789.29 | D15: 57042.34 | E15: 58246.45 | F15: 61613.98 | G15: 59373.16 | H15: 69005.96 | I15: 63974.68 | J15: 55593.97 | K15: 125000 | L15: 125000 | M15: 125000 | N15: =SUM(B15:D15) -> 153963.79 | O15: =SUM(E15:G15) -> 179233.59 | P15: =SUM(H15:J15) -> 188574.61 | Q15: =SUM(K15:M15) -> 375000 | R15: =SUM(B15:M15) -> 896771.99 | S15: 636109.61 | T15: =IF(S15=0,"",R15/S15-1) -> 0.40977589
A16: Total, ten stores | B16: =B14+B15 -> 2558693.9 | C16: =C14+C15 -> 2309932.8 | D16: =D14+D15 -> 2688271.2 | E16: =E14+E15 -> 2639028.1 | F16: =F14+F15 -> 2835538.3 | G16: =G14+G15 -> 2668726 | H16: =H14+H15 -> 2978902.6 | I16: =I14+I15 -> 2912036.4 | ... S16: =S14+S15 -> 28430652 | T16: =IF(S16=0,"",R16/S16-1) -> 0.13231077

Sheet Year to date
A1: Year to date against target
A2: Calculated from 'Monthly tracking': only months with an actual entered count.
A4: Store | B4: Target 2027 | C4: Target to date | D4: Actual to date | E4: Variance $ | F4: Variance % | G4: Months entered
A5: Beverly Hills | B5: ='Targets 2027'!R5 -> 3119407 | C5: =SUMIFS('Monthly tracking'!$C$5:$C$124,'Monthly tracking'!$A$5:$A$124,A5,'Monthly tracking'!$D$5:$D$124,"<>") -> 0 | D5: =SUMIFS('Monthly tracking'!$D$5:$D$124,'Monthly tracking'!$A$5:$A$124,A5) -> 0 | E5: =IF(G5=0,"",D5-C5) | F5: =IF(G5=0,"",D5/C5-1) | G5: =COUNTIFS('Monthly tracking'!$A$5:$A$124,A5,'Monthly tracking'!$D$5:$D$124,"<>") -> 0
A6: Brentwood | B6: ='Targets 2027'!R6 -> 2641664.4 | C6: =SUMIFS('Monthly tracking'!$C$5:$C$124,'Monthly tracking'!$A$5:$A$124,A6,'Monthly tracking'!$D$5:$D$124,"<>") -> 0 | D6: =SUMIFS('Monthly tracking'!$D$5:$D$124,'Monthly tracking'!$A$5:$A$124,A6) -> 0 | E6: =IF(G6=0,"",D6-C6) | F6: =IF(G6=0,"",D6/C6-1) | G6: =COUNTIFS('Monthly tracking'!$A$5:$A$124,A6,'Monthly tracking'!$D$5:$D$124,"<>") -> 0
A7: Carlsbad | B7: ='Targets 2027'!R7 -> 4233666.8 | C7: =SUMIFS('Monthly tracking'!$C$5:$C$124,'Monthly tracking'!$A$5:$A$124,A7,'Monthly tracking'!$D$5:$D$124,"<>") -> 0 | D7: =SUMIFS('Monthly tracking'!$D$5:$D$124,'Monthly tracking'!$A$5:$A$124,A7) -> 0 | E7: =IF(G7=0,"",D7-C7) | F7: =IF(G7=0,"",D7/C7-1) | G7: =COUNTIFS('Monthly tracking'!$A$5:$A$124,A7,'Monthly tracking'!$D$5:$D$124,"<>") -> 0
A8: Coronado | B8: ='Targets 2027'!R8 -> 4307690.7 | C8: =SUMIFS('Monthly tracking'!$C$5:$C$124,'Monthly tracking'!$A$5:$A$124,A8,'Monthly tracking'!$D$5:$D$124,"<>") -> 0 | D8: =SUMIFS('Monthly tracking'!$D$5:$D$124,'Monthly tracking'!$A$5:$A$124,A8) -> 0 | E8: =IF(G8=0,"",D8-C8) | F8: =IF(G8=0,"",D8/C8-1) | G8: =COUNTIFS('Monthly tracking'!$A$5:$A$124,A8,'Monthly tracking'!$D$5:$D$124,"<>") -> 0
A9: Del Mar Café | B9: ='Targets 2027'!R9 -> 5151283.7 | C9: =SUMIFS('Monthly tracking'!$C$5:$C$124,'Monthly tracking'!$A$5:$A$124,A9,'Monthly tracking'!$D$5:$D$124,"<>") -> 0 | D9: =SUMIFS('Monthly tracking'!$D$5:$D$124,'Monthly tracking'!$A$5:$A$124,A9) -> 0 | E9: =IF(G9=0,"",D9-C9) | F9: =IF(G9=0,"",D9/C9-1) | G9: =COUNTIFS('Monthly tracking'!$A$5:$A$124,A9,'Monthly tracking'!$D$5:$D$124,"<>") -> 0
A10: La Jolla Café | B10: ='Targets 2027'!R10 -> 3127558.1 | C10: =SUMIFS('Monthly tracking'!$C$5:$C$124,'Monthly tracking'!$A$5:$A$124,A10,'Monthly tracking'!$D$5:$D$124,"<>") -> 0 | D10: =SUMIFS('Monthly tracking'!$D$5:$D$124,'Monthly tracking'!$A$5:$A$124,A10) -> 0 | E10: =IF(G10=0,"",D10-C10) | F10: =IF(G10=0,"",D10/C10-1) | G10: =COUNTIFS('Monthly tracking'!$A$5:$A$124,A10,'Monthly tracking'!$D$5:$D$124,"<>") -> 0
A11: La Jolla Juicery | B11: ='Targets 2027'!R11 -> 931725.69 | C11: =SUMIFS('Monthly tracking'!$C$5:$C$124,'Monthly tracking'!$A$5:$A$124,A11,'Monthly tracking'!$D$5:$D$124,"<>") -> 0 | D11: =SUMIFS('Monthly tracking'!$D$5:$D$124,'Monthly tracking'!$A$5:$A$124,A11) -> 0 | E11: =IF(G11=0,"",D11-C11) | F11: =IF(G11=0,"",D11/C11-1) | G11: =COUNTIFS('Monthly tracking'!$A$5:$A$124,A11,'Monthly tracking'!$D$5:$D$124,"<>") -> 0
A12: Little Italy Café | B12: ='Targets 2027'!R12 -> 3928095.9 | C12: =SUMIFS('Monthly tracking'!$C$5:$C$124,'Monthly tracking'!$A$5:$A$124,A12,'Monthly tracking'!$D$5:$D$124,"<>") -> 0 | D12: =SUMIFS('Monthly tracking'!$D$5:$D$124,'Monthly tracking'!$A$5:$A$124,A12) -> 0 | E12: =IF(G12=0,"",D12-C12) | F12: =IF(G12=0,"",D12/C12-1) | G12: =COUNTIFS('Monthly tracking'!$A$5:$A$124,A12,'Monthly tracking'!$D$5:$D$124,"<>") -> 0
A13: Newport Beach | B13: ='Targets 2027'!R13 -> 3854468.9 | C13: =SUMIFS('Monthly tracking'!$C$5:$C$124,'Monthly tracking'!$A$5:$A$124,A13,'Monthly tracking'!$D$5:$D$124,"<>") -> 0 | D13: =SUMIFS('Monthly tracking'!$D$5:$D$124,'Monthly tracking'!$A$5:$A$124,A13) -> 0 | E13: =IF(G13=0,"",D13-C13) | F13: =IF(G13=0,"",D13/C13-1) | G13: =COUNTIFS('Monthly tracking'!$A$5:$A$124,A13,'Monthly tracking'!$D$5:$D$124,"<>") -> 0
A14: La Jolla Cove | B14: ='Targets 2027'!R15 -> 896771.99 | C14: =SUMIFS('Monthly tracking'!$C$5:$C$124,'Monthly tracking'!$A$5:$A$124,A14,'Monthly tracking'!$D$5:$D$124,"<>") -> 0 | D14: =SUMIFS('Monthly tracking'!$D$5:$D$124,'Monthly tracking'!$A$5:$A$124,A14) -> 0 | E14: =IF(G14=0,"",D14-C14) | F14: =IF(G14=0,"",D14/C14-1) | G14: =COUNTIFS('Monthly tracking'!$A$5:$A$124,A14,'Monthly tracking'!$D$5:$D$124,"<>") -> 0
A15: Total, ten stores | B15: =SUM(B5:B14) -> 32192333 | C15: =SUM(C5:C14) -> 0 | D15: =SUM(D5:D14) -> 0 | E15: =IF(D15=0,"",D15-C15) | F15: =IF(D15=0,"",D15/C15-1)

Sheet Monthly tracking
A1: Monthly tracking: enter each month's actual net sales in the cream cells
A2: Targets link to 'Targets 2027' (green). Variances fill in once an actual is entered.
A4: Store | B4: Month | C4: Target | D4: Actual | E4: Variance $ | F4: Variance % | H4: How to fill in
A5: Beverly Hills | B5: Jan 2027 | C5: ='Targets 2027'!B5 -> 240335.44 | E5: =IF(D5="","",D5-C5) | F5: =IF(D5="","",D5/C5-1) | H5: 1. When a month closes, type the store's actual net sales from Toast, in dollars, in its cream cell (column D).
A6: Beverly Hills | B6: Feb 2027 | C6: ='Targets 2027'!C5 -> 232184.11 | E6: =IF(D6="","",D6-C6) | F6: =IF(D6="","",D6/C6-1) | H6: 2. Variance $ and % fill in on their own; the 'Year to date' tab adds up the months entered.
A7: Beverly Hills | B7: Mar 2027 | C7: ='Targets 2027'!D5 -> 257387.11 | E7: =IF(D7="","",D7-C7) | F7: =IF(D7="","",D7/C7-1) | H7: 3. Leave months blank until they close. Targets (green) link to 'Targets 2027': change them there.
A8: Beverly Hills | B8: Apr 2027 | C8: ='Targets 2027'!E5 -> 248190.77 | E8: =IF(D8="","",D8-C8) | F8: =IF(D8="","",D8/C8-1) | H8: Colors: blue = typed values · black = formulas · green = links to another tab.
A9: Beverly Hills | B9: May 2027 | C9: ='Targets 2027'!F5 -> 272444.59 | E9: =IF(D9="","",D9-C9) | F9: =IF(D9="","",D9/C9-1)
A10: Beverly Hills | B10: Jun 2027 | C10: ='Targets 2027'!G5 -> 263775.07 | E10: =IF(D10="","",D10-C10) | F10: =IF(D10="","",D10/C10-1) | H10: Example (not counted)
A11: Beverly Hills | B11: Jul 2027 | C11: ='Targets 2027'!H5 -> 269201.25 | E11: =IF(D11="","",D11-C11) | F11: =IF(D11="","",D11/C11-1) | H11: Store | I11: Month | J11: Target | K11: Actual | L11: Variance $ | M11: Variance %
A12: Beverly Hills | B12: Aug 2027 | C12: ='Targets 2027'!I5 -> 281751.13 | E12: =IF(D12="","",D12-C12) | F12: =IF(D12="","",D12/C12-1) | H12: Beverly Hills | I12: Jan 2027 | J12: =C5 -> 240335.44 | K12: 245000 | L12: =IF(K12="","",K12-J12) -> 4664.56 | M12: =IF(K12="","",K12/J12-1) -> 0.01940854
A13: Beverly Hills | B13: Sep 2027 | C13: ='Targets 2027'!J5 -> 256443.1 | E13: =IF(D13="","",D13-C13) | F13: =IF(D13="","",D13/C13-1)
A14: Beverly Hills | B14: Oct 2027 | C14: ='Targets 2027'!K5 -> 265311.55 | E14: =IF(D14="","",D14-C14) | F14: =IF(D14="","",D14/C14-1)
A15: Beverly Hills | B15: Nov 2027 | C15: ='Targets 2027'!L5 -> 266803.98 | E15: =IF(D15="","",D15-C15) | F15: =IF(D15="","",D15/C15-1)
A16: Beverly Hills | B16: Dec 2027 | C16: ='Targets 2027'!M5 -> 265578.91 | E16: =IF(D16="","",D16-C16) | F16: =IF(D16="","",D16/C16-1)
A17: Brentwood | B17: Jan 2027 | C17: ='Targets 2027'!B6 -> 227289.23 | E17: =IF(D17="","",D17-C17) | F17: =IF(D17="","",D17/C17-1)
A18: Brentwood | B18: Feb 2027 | C18: ='Targets 2027'!C6 -> 203905.78 | E18: =IF(D18="","",D18-C18) | F18: =IF(D18="","",D18/C18-1)
A19: Brentwood | B19: Mar 2027 | C19: ='Targets 2027'!D6 -> 222438.88 | E19: =IF(D19="","",D19-C19) | F19: =IF(D19="","",D19/C19-1)
A20: Brentwood | B20: Apr 2027 | C20: ='Targets 2027'!E6 -> 214066.03 | E20: =IF(D20="","",D20-C20) | F20: =IF(D20="","",D20/C20-1)
A21: Brentwood | B21: May 2027 | C21: ='Targets 2027'!F6 -> 230110.53 | E21: =IF(D21="","",D21-C21) | F21: =IF(D21="","",D21/C21-1)
A22: Brentwood | B22: Jun 2027 | C22: ='Targets 2027'!G6 -> 204562.27 | E22: =IF(D22="","",D22-C22) | F22: =IF(D22="","",D22/C22-1)
A23: Brentwood | B23: Jul 2027 | C23: ='Targets 2027'!H6 -> 205433.25 | E23: =IF(D23="","",D23-C23) | F23: =IF(D23="","",D23/C23-1)
A24: Brentwood | B24: Aug 2027 | C24: ='Targets 2027'!I6 -> 216074.01 | E24: =IF(D24="","",D24-C24) | F24: =IF(D24="","",D24/C24-1)
A25: Brentwood | B25: Sep 2027 | C25: ='Targets 2027'!J6 -> 215120.82 | E25: =IF(D25="","",D25-C25) | F25: =IF(D25="","",D25/C25-1)
A26: Brentwood | B26: Oct 2027 | C26: ='Targets 2027'!K6 -> 238271.16 | E26: =IF(D26="","",D26-C26) | F26: =IF(D26="","",D26/C26-1)
A27: Brentwood | B27: Nov 2027 | C27: ='Targets 2027'!L6 -> 237928.07 | E27: =IF(D27="","",D27-C27) | F27: =IF(D27="","",D27/C27-1)
A28: Brentwood | B28: Dec 2027 | C28: ='Targets 2027'!M6 -> 226464.41 | E28: =IF(D28="","",D28-C28) | F28: =IF(D28="","",D28/C28-1)
A29: Carlsbad | B29: Jan 2027 | C29: ='Targets 2027'!B7 -> 347155.87 | E29: =IF(D29="","",D29-C29) | F29: =IF(D29="","",D29/C29-1)
A30: Carlsbad | B30: Feb 2027 | C30: ='Targets 2027'!C7 -> 303859.01 | E30: =IF(D30="","",D30-C30) | F30: =IF(D30="","",D30/C30-1)
A31: Carlsbad | B31: Mar 2027 | C31: ='Targets 2027'!D7 -> 350055.72 | E31: =IF(D31="","",D31-C31) | F31: =IF(D31="","",D31/C31-1)
A32: Carlsbad | B32: Apr 2027 | C32: ='Targets 2027'!E7 -> 355295.68 | E32: =IF(D32="","",D32-C32) | F32: =IF(D32="","",D32/C32-1)
A33: Carlsbad | B33: May 2027 | C33: ='Targets 2027'!F7 -> 381551.8 | E33: =IF(D33="","",D33-C33) | F33: =IF(D33="","",D33/C33-1)
A34: Carlsbad | B34: Jun 2027 | C34: ='Targets 2027'!G7 -> 347223.39 | E34: =IF(D34="","",D34-C34) | F34: =IF(D34="","",D34/C34-1)
A35: Carlsbad | B35: Jul 2027 | C35: ='Targets 2027'!H7 -> 370112.79 | E35: =IF(D35="","",D35-C35) | F35: =IF(D35="","",D35/C35-1)
A36: Carlsbad | B36: Aug 2027 | C36: ='Targets 2027'!I7 -> 362058.09 | E36: =IF(D36="","",D36-C36) | F36: =IF(D36="","",D36/C36-1)
A37: Carlsbad | B37: Sep 2027 | C37: ='Targets 2027'!J7 -> 325338.38 | E37: =IF(D37="","",D37-C37) | F37: =IF(D37="","",D37/C37-1)
A38: Carlsbad | B38: Oct 2027 | C38: ='Targets 2027'!K7 -> 343803.24 | E38: =IF(D38="","",D38-C38) | F38: =IF(D38="","",D38/C38-1)
A39: Carlsbad | B39: Nov 2027 | C39: ='Targets 2027'!L7 -> 356440.28 | E39: =IF(D39="","",D39-C39) | F39: =IF(D39="","",D39/C39-1)
A40: Carlsbad | B40: Dec 2027 | C40: ='Targets 2027'!M7 -> 390772.6 | E40: =IF(D40="","",D40-C40) | F40: =IF(D40="","",D40/C40-1)
A41: Coronado | B41: Jan 2027 | C41: ='Targets 2027'!B8 -> 312399.46 | E41: =IF(D41="","",D41-C41) | F41: =IF(D41="","",D41/C41-1)
...

Sheet Reference
A1: Reference: 2026 finish and 2027 under each view
A2: Sources: Toast POS net sales through Oct 14, 2026; investor budget workbook (2027_Sales_budget_Investors.xlsx); run-rate = last 45 days seasonally adjusted; target = our plan.
A4: Store | B4: 2025 actual (Toast) | C4: 2026 finish: budget | D4: 2026 finish: run-rate | E4: 2027: budget | F4: 2027: run-rate objective | G4: 2027: target | H4: Target vs budget
A5: Beverly Hills | B5: 1911404.6 | C5: 2577341.9 | D5: 2606461.4 | E5: 2757755.8 | F5: 2897107.2 | G5: ='Targets 2027'!R5 -> 3119407 | H5: =G5-E5 -> 361651.2
A6: Brentwood | B6: 1867961.5 | C6: 2340528.3 | D6: 2302939.3 | E6: 2363933.6 | F6: 2345912.7 | G6: ='Targets 2027'!R6 -> 2641664.4 | H6: =G6-E6 -> 277730.83
A7: Carlsbad | B7: 3339194.5 | C7: 3696858 | D7: 3723643.2 | E7: 3807763.8 | F7: 3868254.8 | G7: ='Targets 2027'!R7 -> 4233666.8 | H7: =G7-E7 -> 425903.09
A8: Coronado | B8: 3525672.5 | C8: 4014075.1 | D8: 3987463.8 | E8: 4134497.4 | F8: 3929309.6 | G8: ='Targets 2027'!R8 -> 4307690.7 | H8: =G8-E8 -> 173193.33
A9: Del Mar Café | B9: 4244562.4 | C9: 4663245.7 | D9: 4665803.1 | E9: 4709878.2 | F9: 4821807.3 | G9: ='Targets 2027'!R9 -> 5151283.7 | H9: =G9-E9 -> 441405.5
A10: La Jolla Café | B10: 2737985 | C10: 2924762.7 | D10: 2904088.3 | E10: 3041753.2 | F10: 3000147.8 | G10: ='Targets 2027'!R10 -> 3127558.1 | H10: =G10-E10 -> 85804.91
A11: La Jolla Juicery | B11: 792954.62 | C11: 900742.27 | D11: 891089.16 | E11: 936771.96 | F11: 880008.54 | G11: ='Targets 2027'!R11 -> 931725.69 | H11: =G11-E11 -> -5046.27
A12: Little Italy Café | B12: 2568994.8 | C12: 3293832 | D12: 3248637.5 | E12: 3458523.6 | F12: 3484427 | G12: ='Targets 2027'!R12 -> 3928095.9 | H12: =G12-E12 -> 469572.37
A13: Newport Beach | B13: 3175196.7 | C13: 3468263.8 | D13: 3464416.6 | E13: 3606994.4 | F13: 3485293.3 | G13: ='Targets 2027'!R13 -> 3854468.9 | H13: =G13-E13 -> 247474.57
A14: La Jolla Cove | B14: 648249.04 | C14: 628179.4 | D14: 636109.61 | E14: 867759.12 | F14: 868322.35 | G14: ='Targets 2027'!R15 -> 896771.99 | H14: =G14-E14 -> 29012.87
A15: Total, ten stores | B15: =SUM(B5:B14) -> 24812176 | C15: =SUM(C5:C14) -> 28507829 | D15: =SUM(D5:D14) -> 28430652 | E15: =SUM(E5:E14) -> 29685631 | F15: =SUM(F5:F14) -> 29580590 | G15: =SUM(G5:G14) -> 32192333 | H15: =SUM(H5:H14) -> 2506702.4
A17: La Jolla Cove's run-rate objective and target include the budget's remodeled $125K a month from Oct 1, 2027. New cafés are not included.
